Workbook

Sheet עסקאות
A1: תאריך | B1: יום | C1: שעה | D1: טיקר | E1: סוג | F1: כמות | G1: מחיר יציאה | H1: מכפיל | I1: תמורה ($) | J1: תוצאה נטו ($) | K1: פרמיה ששולמה ($) | L1: מחיר כניסה | M1: % מהפרמיה | N1: החזקה (דק׳) | O1: עמלה ($)
A2: 46258 | B2: שני | C2: 00:02 | D2: CL | E2: FUT | F2: 2 | G2: 85.61 | H2: =IF(F2*G2=0,"",ROUND(I2/(F2*G2),0)) | I2: 171220 | J2: -449.44 | K2: =I2-J2 | L2: =IF(OR(F2=0,H2=""),"",K2/(F2*H2)) | M2: =IF(K2=0,"",J2/K2) | N2: 190.8 | O2: 4.72
A3: 46258 | B3: שני | C3: 00:03 | D3: NQ | E3: FOP | F3: 6 | G3: 5.5 | H3: =IF(F3*G3=0,"",ROUND(I3/(F3*G3),0)) | I3: 660 | J3: 0 | K3: =I3-J3 | L3: =IF(OR(F3=0,H3=""),"",K3/(F3*H3)) | M3: =IF(K3=0,"",J3/K3) | N3: 0 | O3: 8.46
A4: 46258 | B4: שני | C4: 01:36 | D4: NQ | E4: FOP | F4: 1 | G4: 31.75 | H4: =IF(F4*G4=0,"",ROUND(I4/(F4*G4),0)) | I4: 635 | J4: 37.18 | K4: =I4-J4 | L4: =IF(OR(F4=0,H4=""),"",K4/(F4*H4)) | M4: =IF(K4=0,"",J4/K4) | O4: 1.41
A5: 46258 | B5: שני | C5: 04:20 | D5: NQ | E5: FOP | F5: 8 | G5: 8.5 | H5: =IF(F5*G5=0,"",ROUND(I5/(F5*G5),0)) | I5: 1360 | J5: -902.56 | K5: =I5-J5 | L5: =IF(OR(F5=0,H5=""),"",K5/(F5*H5)) | M5: =IF(K5=0,"",J5/K5) | N5: 128.2 | O5: 11.28
A6: 46258 | B6: שני | C6: 07:40 | D6: NQ | E6: FOP | F6: 5 | G6: 27 | H6: =IF(F6*G6=0,"",ROUND(I6/(F6*G6),0)) | I6: 2700 | J6: -289.1 | K6: =I6-J6 | L6: =IF(OR(F6=0,H6=""),"",K6/(F6*H6)) | M6: =IF(K6=0,"",J6/K6) | N6: 0 | O6: 7.05
A7: 46258 | B7: שני | C7: 09:33 | D7: MU | E7: OPT | F7: 7 | G7: 5.15 | H7: =IF(F7*G7=0,"",ROUND(I7/(F7*G7),0)) | I7: 3605 | J7: 3250.16 | K7: =I7-J7 | L7: =IF(OR(F7=0,H7=""),"",K7/(F7*H7)) | M7: =IF(K7=0,"",J7/K7) | N7: 119.1 | O7: 1.97
A8: 46258 | B8: שני | C8: 09:35 | D8: MRNA | E8: OPT | F8: 11 | G8: 0.3 | H8: =IF(F8*G8=0,"",ROUND(I8/(F8*G8),0)) | I8: 330 | J8: -830.77 | K8: =I8-J8 | L8: =IF(OR(F8=0,H8=""),"",K8/(F8*H8)) | M8: =IF(K8=0,"",J8/K8) | O8: 3.2
A9: 46258 | B9: שני | C9: 09:40 | D9: MU | E9: OPT | F9: 3 | G9: 7 | H9: =IF(F9*G9=0,"",ROUND(I9/(F9*G9),0)) | I9: 2100 | J9: 1947.91 | K9: =I9-J9 | L9: =IF(OR(F9=0,H9=""),"",K9/(F9*H9)) | M9: =IF(K9=0,"",J9/K9) | O9: 0.86
A10: 46258 | B10: שני | C10: 09:48 | D10: NVDA | E10: OPT | F10: 55 | G10: 0.47 | H10: =IF(F10*G10=0,"",ROUND(I10/(F10*G10),0)) | I10: 2585 | J10: 339.23 | K10: =I10-J10 | L10: =IF(OR(F10=0,H10=""),"",K10/(F10*H10)) | M10: =IF(K10=0,"",J10/K10) | N10: 5.2 | O10: 28.94
A11: 46258 | B11: שני | C11: 09:52 | D11: MU | E11: OPT | F11: 5 | G11: 10 | H11: =IF(F11*G11=0,"",ROUND(I11/(F11*G11),0)) | I11: 5000 | J11: 4746.49 | K11: =I11-J11 | L11: =IF(OR(F11=0,H11=""),"",K11/(F11*H11)) | M11: =IF(K11=0,"",J11/K11) | O11: 1.46
A12: 46258 | B12: שני | C12: 10:12 | D12: GC | E12: FOP | F12: 5 | G12: 2.7 | H12: =IF(F12*G12=0,"",ROUND(I12/(F12*G12),0)) | I12: 1350 | J12: -1275.1 | K12: =I12-J12 | L12: =IF(OR(F12=0,H12=""),"",K12/(F12*H12)) | M12: =IF(K12=0,"",J12/K12) | N12: 63.6 | O12: 12.55
A13: 46258 | B13: שני | C13: 10:14 | D13: ANET | E13: OPT | F13: 46 | G13: 0.12 | H13: =IF(F13*G13=0,"",ROUND(I13/(F13*G13),0)) | I13: 552 | J13: -1409.28 | K13: =I13-J13 | L13: =IF(OR(F13=0,H13=""),"",K13/(F13*H13)) | M13: =IF(K13=0,"",J13/K13) | O13: 22.02
A14: 46258 | B14: שני | C14: 10:14 | D14: ANET | E14: OPT | F14: 5 | G14: 0.11 | H14: =IF(F14*G14=0,"",ROUND(I14/(F14*G14),0)) | I14: 55 | J14: -156.73 | K14: =I14-J14 | L14: =IF(OR(F14=0,H14=""),"",K14/(F14*H14)) | M14: =IF(K14=0,"",J14/K14) | O14: 0.94
A15: 46258 | B15: שני | C15: 10:21 | D15: MU | E15: OPT | F15: 15 | G15: 8.1 | H15: =IF(F15*G15=0,"",ROUND(I15/(F15*G15),0)) | I15: 12150 | J15: 11385.42 | K15: =I15-J15 | L15: =IF(OR(F15=0,H15=""),"",K15/(F15*H15)) | M15: =IF(K15=0,"",J15/K15) | O15: 8.42
A16: 46258 | B16: שני | C16: 10:21 | D16: QQQ | E16: OPT | F16: 80 | G16: 0.14 | H16: =IF(F16*G16=0,"",ROUND(I16/(F16*G16),0)) | I16: 1120 | J16: -928.47 | K16: =I16-J16 | L16: =IF(OR(F16=0,H16=""),"",K16/(F16*H16)) | M16: =IF(K16=0,"",J16/K16) | N16: 33.7 | O16: 51.66
A17: 46258 | B17: שני | C17: 10:30 | D17: MU | E17: OPT | F17: 1 | G17: 1.6 | H17: =IF(F17*G17=0,"",ROUND(I17/(F17*G17),0)) | I17: 160 | J17: -86.04 | K17: =I17-J17 | L17: =IF(OR(F17=0,H17=""),"",K17/(F17*H17)) | M17: =IF(K17=0,"",J17/K17) | O17: 0.77
A18: 46258 | B18: שני | C18: 10:32 | D18: MU | E18: OPT | F18: 2 | G18: 1.03 | H18: =IF(F18*G18=0,"",ROUND(I18/(F18*G18),0)) | I18: 206 | J18: -285.08 | K18: =I18-J18 | L18: =IF(OR(F18=0,H18=""),"",K18/(F18*H18)) | M18: =IF(K18=0,"",J18/K18) | O18: 0.55
A19: 46258 | B19: שני | C19: 10:32 | D19: MU | E19: OPT | F19: 7 | G19: 1.05 | H19: =IF(F19*G19=0,"",ROUND(I19/(F19*G19),0)) | I19: 735 | J19: -983.84 | K19: =I19-J19 | L19: =IF(OR(F19=0,H19=""),"",K19/(F19*H19)) | M19: =IF(K19=0,"",J19/K19) | O19: 1.97
A20: 46258 | B20: שני | C20: 10:32 | D20: MU | E20: OPT | F20: 10 | G20: 1.08 | H20: =IF(F20*G20=0,"",ROUND(I20/(F20*G20),0)) | I20: 1080 | J20: -1375.6 | K20: =I20-J20 | L20: =IF(OR(F20=0,H20=""),"",K20/(F20*H20)) | M20: =IF(K20=0,"",J20/K20) | O20: 2.93
A21: 46258 | B21: שני | C21: 11:04 | D21: AAOI | E21: OPT | F21: 25 | G21: 0.65 | H21: =IF(F21*G21=0,"",ROUND(I21/(F21*G21),0)) | I21: 1625 | J21: -481.53 | K21: =I21-J21 | L21: =IF(OR(F21=0,H21=""),"",K21/(F21*H21)) | M21: =IF(K21=0,"",J21/K21) | N21: 9.4 | O21: -2.45
A22: 46258 | B22: שני | C22: 11:13 | D22: MU | E22: OPT | F22: 25 | G22: 0.49 | H22: =IF(F22*G22=0,"",ROUND(I22/(F22*G22),0)) | I22: 1225 | J22: -662.05 | K22: =I22-J22 | L22: =IF(OR(F22=0,H22=""),"",K22/(F22*H22)) | M22: =IF(K22=0,"",J22/K22) | O22: 6.79
A23: 46258 | B23: שני | C23: 11:29 | D23: MU | E23: OPT | F23: 20 | G23: 0.33 | H23: =IF(F23*G23=0,"",ROUND(I23/(F23*G23),0)) | I23: 660 | J23: -1151.05 | K23: =I23-J23 | L23: =IF(OR(F23=0,H23=""),"",K23/(F23*H23)) | M23: =IF(K23=0,"",J23/K23) | O23: 5.43
A24: 46258 | B24: שני | C24: 12:40 | D24: CRM | E24: OPT | F24: 70 | G24: 0.16 | H24: =IF(F24*G24=0,"",ROUND(I24/(F24*G24),0)) | I24: 1120 | J24: -947.68 | K24: =I24-J24 | L24: =IF(OR(F24=0,H24=""),"",K24/(F24*H24)) | M24: =IF(K24=0,"",J24/K24) | N24: 120 | O24: 18.96
A25: 46258 | B25: שני | C25: 12:46 | D25: MU | E25: OPT | F25: 18 | G25: 0.68 | H25: =IF(F25*G25=0,"",ROUND(I25/(F25*G25),0)) | I25: 1224 | J25: -793.97 | K25: =I25-J25 | L25: =IF(OR(F25=0,H25=""),"",K25/(F25*H25)) | M25: =IF(K25=0,"",J25/K25) | O25: 4.9
A26: 46258 | B26: שני | C26: 13:08 | D26: CL | E26: FOP | F26: 20 | G26: 0.09 | H26: =IF(F26*G26=0,"",ROUND(I26/(F26*G26),0)) | I26: 1800 | J26: -1964.4 | K26: =I26-J26 | L26: =IF(OR(F26=0,H26=""),"",K26/(F26*H26)) | M26: =IF(K26=0,"",J26/K26) | N26: 129.9 | O26: 47.2
A27: 46258 | B27: שני | C27: 13:13 | D27: MU | E27: OPT | F27: 18 | G27: 0.67 | H27: =IF(F27*G27=0,"",ROUND(I27/(F27*G27),0)) | I27: 1206 | J27: -495.71 | K27: =I27-J27 | L27: =IF(OR(F27=0,H27=""),"",K27/(F27*H27)) | M27: =IF(K27=0,"",J27/K27) | O27: 4.9
A28: 46258 | B28: שני | C28: 13:14 | D28: AMZN | E28: OPT | F28: 50 | G28: 0.42 | H28: =IF(F28*G28=0,"",ROUND(I28/(F28*G28),0)) | I28: 2100 | J28: 87.32 | K28: =I28-J28 | L28: =IF(OR(F28=0,H28=""),"",K28/(F28*H28)) | M28: =IF(K28=0,"",J28/K28) | N28: 157 | O28: 8.49
A29: 46258 | B29: שני | C29: 14:13 | D29: MU | E29: OPT | F29: 33 | G29: 0.36 | H29: =IF(F29*G29=0,"",ROUND(I29/(F29*G29),0)) | I29: 1188 | J29: -488.37 | K29: =I29-J29 | L29: =IF(OR(F29=0,H29=""),"",K29/(F29*H29)) | M29: =IF(K29=0,"",J29/K29) | N29: 6.5 | O29: 14.06
A30: 46258 | B30: שני | C30: 14:36 | D30: MU | E30: OPT | F30: 1 | G30: 0.5 | H30: =IF(F30*G30=0,"",ROUND(I30/(F30*G30),0)) | I30: 50 | J30: -21.7 | K30: =I30-J30 | L30: =IF(OR(F30=0,H30=""),"",K30/(F30*H30)) | M30: =IF(K30=0,"",J30/K30) | O30: 0.79
A31: 46258 | B31: שני | C31: 14:37 | D31: MU | E31: OPT | F31: 1 | G31: 0.39 | H31: =IF(F31*G31=0,"",ROUND(I31/(F31*G31),0)) | I31: 39 | J31: -32.26 | K31: =I31-J31 | L31: =IF(OR(F31=0,H31=""),"",K31/(F31*H31)) | M31: =IF(K31=0,"",J31/K31) | O31: 0.35
A32: 46258 | B32: שני | C32: 14:37 | D32: MU | E32: OPT | F32: 28 | G32: 0.4 | H32: =IF(F32*G32=0,"",ROUND(I32/(F32*G32),0)) | I32: 1120 | J32: -873.69 | K32: =I32-J32 | L32: =IF(OR(F32=0,H32=""),"",K32/(F32*H32)) | M32: =IF(K32=0,"",J32/K32) | O32: 8.17
A33: 46258 | B33: שני | C33: 15:19 | D33: CRM | E33: OPT | F33: 2 | G33: 0.12 | H33: =IF(F33*G33=0,"",ROUND(I33/(F33*G33),0)) | I33: 24 | J33: -4.91 | K33: =I33-J33 | L33: =IF(OR(F33=0,H33=""),"",K33/(F33*H33)) | M33: =IF(K33=0,"",J33/K33) | N33: 1.8 | O33: 0.54
A34: 46259 | B34: שלישי | C34: 09:55 | D34: MSTR | E34: OPT | F34: 45 | G34: 0.19 | H34: =IF(F34*G34=0,"",ROUND(I34/(F34*G34),0)) | I34: 855 | J34: -977.62 | K34: =I34-J34 | L34: =IF(OR(F34=0,H34=""),"",K34/(F34*H34)) | M34: =IF(K34=0,"",J34/K34) | N34: 1177.2 | O34: 20.59
A35: 46259 | B35: שלישי | C35: 09:58 | D35: QQQ | E35: OPT | F35: 60 | G35: 0.14 | H35: =IF(F35*G35=0,"",ROUND(I35/(F35*G35),0)) | I35: 840 | J35: -1192.9 | K35: =I35-J35 | L35: =IF(OR(F35=0,H35=""),"",K35/(F35*H35)) | M35: =IF(K35=0,"",J35/K35) | N35: 10.6 | O35: 28.4
A36: 46259 | B36: שלישי | C36: 10:03 | D36: AMZN | E36: OPT | F36: 50 | G36: 0.14 | H36: =IF(F36*G36=0,"",ROUND(I36/(F36*G36),0)) | I36: 700 | J36: -1227.69 | K36: =I36-J36 | L36: =IF(OR(F36=0,H36=""),"",K36/(F36*H36)) | M36: =IF(K36=0,"",J36/K36) | N36: 1090.1 | O36: 6.57
A37: 46259 | B37: שלישי | C37: 10:03 | D37: CRM | E37: OPT | F37: 10 | G37: 0.53 | H37: =IF(F37*G37=0,"",ROUND(I37/(F37*G37),0)) | I37: 530 | J37: -435.39 | K37: =I37-J37 | L37: =IF(OR(F37=0,H37=""),"",K37/(F37*H37)) | M37: =IF(K37=0,"",J37/K37) | N37: 1125.9 | O37: 2.72
A38: 46259 | B38: שלישי | C38: 11:05 | D38: SMCI | E38: OPT | F38: 40 | G38: 0.36 | H38: =IF(F38*G38=0,"",ROUND(I38/(F38*G38),0)) | I38: 1440 | J38: -693.07 | K38: =I38-J38 | L38: =IF(OR(F38=0,H38=""),"",K38/(F38*H38)) | M38: =IF(K38=0,"",J38/K38) | N38: 16.2 | O38: 2.37
A39: 46259 | B39: שלישי | C39: 11:16 | D39: ES | E39: FOP | F39: 17 | G39: 1.4 | H39: =IF(F39*G39=0,"",ROUND(I39/(F39*G39),0)) | I39: 1190 | J39: -621.69 | K39: =I39-J39 | L39: =IF(OR(F39=0,H39=""),"",K39/(F39*H39)) | M39: =IF(K39=0,"",J39/K39) | N39: 69.5 | O39: 23.97
A40: 46259 | B40: שלישי | C40: 11:16 | D40: ES | E40: FOP | F40: 3 | G40: 1.45 | H40: =IF(F40*G40=0,"",ROUND(I40/(F40*G40),0)) | I40: 217.5 | J40: -102.21 | K40: =I40-J40 | L40: =IF(OR(F40=0,H40=""),"",K40/(F40*H40)) | M40: =IF(K40=0,"",J40/K40) | N40: 72.6 | O40: 4.23
...

Sheet לפי טיקר
A1: טיקר | B1: יציאות | C1: זוכות | D1: חוזים | E1: פרמיה ($) | F1: תוצאה נטו ($) | G1: % מהפרמיה
A2: CRM | B2: =COUNTIF(עסקאות!$D$2:$D$108,$A2) | C2: =COUNTIFS(עסקאות!$D$2:$D$108,$A2,עסקאות!$J$2:$J$108,">0") | D2: =SUMIF(עסקאות!$D$2:$D$108,$A2,עסקאות!$F$2:$F$108) | E2: =SUMIF(עסקאות!$D$2:$D$108,$A2,עסקאות!$K$2:$K$108) | F2: =SUMIF(עסקאות!$D$2:$D$108,$A2,עסקאות!$J$2:$J$108) | G2: =IF(E2=0,"",F2/E2)
A3: MU | B3: =COUNTIF(עסקאות!$D$2:$D$108,$A3) | C3: =COUNTIFS(עסקאות!$D$2:$D$108,$A3,עסקאות!$J$2:$J$108,">0") | D3: =SUMIF(עסקאות!$D$2:$D$108,$A3,עסקאות!$F$2:$F$108) | E3: =SUMIF(עסקאות!$D$2:$D$108,$A3,עסקאות!$K$2:$K$108) | F3: =SUMIF(עסקאות!$D$2:$D$108,$A3,עסקאות!$J$2:$J$108) | G3: =IF(E3=0,"",F3/E3)
A4: PLTR | B4: =COUNTIF(עסקאות!$D$2:$D$108,$A4) | C4: =COUNTIFS(עסקאות!$D$2:$D$108,$A4,עסקאות!$J$2:$J$108,">0") | D4: =SUMIF(עסקאות!$D$2:$D$108,$A4,עסקאות!$F$2:$F$108) | E4: =SUMIF(עסקאות!$D$2:$D$108,$A4,עסקאות!$K$2:$K$108) | F4: =SUMIF(עסקאות!$D$2:$D$108,$A4,עסקאות!$J$2:$J$108) | G4: =IF(E4=0,"",F4/E4)
A5: TSLA | B5: =COUNTIF(עסקאות!$D$2:$D$108,$A5) | C5: =COUNTIFS(עסקאות!$D$2:$D$108,$A5,עסקאות!$J$2:$J$108,">0") | D5: =SUMIF(עסקאות!$D$2:$D$108,$A5,עסקאות!$F$2:$F$108) | E5: =SUMIF(עסקאות!$D$2:$D$108,$A5,עסקאות!$K$2:$K$108) | F5: =SUMIF(עסקאות!$D$2:$D$108,$A5,עסקאות!$J$2:$J$108) | G5: =IF(E5=0,"",F5/E5)
A6: AAOI | B6: =COUNTIF(עסקאות!$D$2:$D$108,$A6) | C6: =COUNTIFS(עסקאות!$D$2:$D$108,$A6,עסקאות!$J$2:$J$108,">0") | D6: =SUMIF(עסקאות!$D$2:$D$108,$A6,עסקאות!$F$2:$F$108) | E6: =SUMIF(עסקאות!$D$2:$D$108,$A6,עסקאות!$K$2:$K$108) | F6: =SUMIF(עסקאות!$D$2:$D$108,$A6,עסקאות!$J$2:$J$108) | G6: =IF(E6=0,"",F6/E6)
A7: SMCI | B7: =COUNTIF(עסקאות!$D$2:$D$108,$A7) | C7: =COUNTIFS(עסקאות!$D$2:$D$108,$A7,עסקאות!$J$2:$J$108,">0") | D7: =SUMIF(עסקאות!$D$2:$D$108,$A7,עסקאות!$F$2:$F$108) | E7: =SUMIF(עסקאות!$D$2:$D$108,$A7,עסקאות!$K$2:$K$108) | F7: =SUMIF(עסקאות!$D$2:$D$108,$A7,עסקאות!$J$2:$J$108) | G7: =IF(E7=0,"",F7/E7)
A8: AMZN | B8: =COUNTIF(עסקאות!$D$2:$D$108,$A8) | C8: =COUNTIFS(עסקאות!$D$2:$D$108,$A8,עסקאות!$J$2:$J$108,">0") | D8: =SUMIF(עסקאות!$D$2:$D$108,$A8,עסקאות!$F$2:$F$108) | E8: =SUMIF(עסקאות!$D$2:$D$108,$A8,עסקאות!$K$2:$K$108) | F8: =SUMIF(עסקאות!$D$2:$D$108,$A8,עסקאות!$J$2:$J$108) | G8: =IF(E8=0,"",F8/E8)
A9: MSFT | B9: =COUNTIF(עסקאות!$D$2:$D$108,$A9) | C9: =COUNTIFS(עסקאות!$D$2:$D$108,$A9,עסקאות!$J$2:$J$108,">0") | D9: =SUMIF(עסקאות!$D$2:$D$108,$A9,עסקאות!$F$2:$F$108) | E9: =SUMIF(עסקאות!$D$2:$D$108,$A9,עסקאות!$K$2:$K$108) | F9: =SUMIF(עסקאות!$D$2:$D$108,$A9,עסקאות!$J$2:$J$108) | G9: =IF(E9=0,"",F9/E9)
A10: NQ | B10: =COUNTIF(עסקאות!$D$2:$D$108,$A10) | C10: =COUNTIFS(עסקאות!$D$2:$D$108,$A10,עסקאות!$J$2:$J$108,">0") | D10: =SUMIF(עסקאות!$D$2:$D$108,$A10,עסקאות!$F$2:$F$108) | E10: =SUMIF(עסקאות!$D$2:$D$108,$A10,עסקאות!$K$2:$K$108) | F10: =SUMIF(עסקאות!$D$2:$D$108,$A10,עסקאות!$J$2:$J$108) | G10: =IF(E10=0,"",F10/E10)
A11: NOW | B11: =COUNTIF(עסקאות!$D$2:$D$108,$A11) | C11: =COUNTIFS(עסקאות!$D$2:$D$108,$A11,עסקאות!$J$2:$J$108,">0") | D11: =SUMIF(עסקאות!$D$2:$D$108,$A11,עסקאות!$F$2:$F$108) | E11: =SUMIF(עסקאות!$D$2:$D$108,$A11,עסקאות!$K$2:$K$108) | F11: =SUMIF(עסקאות!$D$2:$D$108,$A11,עסקאות!$J$2:$J$108) | G11: =IF(E11=0,"",F11/E11)
A12: ES | B12: =COUNTIF(עסקאות!$D$2:$D$108,$A12) | C12: =COUNTIFS(עסקאות!$D$2:$D$108,$A12,עסקאות!$J$2:$J$108,">0") | D12: =SUMIF(עסקאות!$D$2:$D$108,$A12,עסקאות!$F$2:$F$108) | E12: =SUMIF(עסקאות!$D$2:$D$108,$A12,עסקאות!$K$2:$K$108) | F12: =SUMIF(עסקאות!$D$2:$D$108,$A12,עסקאות!$J$2:$J$108) | G12: =IF(E12=0,"",F12/E12)
A13: GC | B13: =COUNTIF(עסקאות!$D$2:$D$108,$A13) | C13: =COUNTIFS(עסקאות!$D$2:$D$108,$A13,עסקאות!$J$2:$J$108,">0") | D13: =SUMIF(עסקאות!$D$2:$D$108,$A13,עסקאות!$F$2:$F$108) | E13: =SUMIF(עסקאות!$D$2:$D$108,$A13,עסקאות!$K$2:$K$108) | F13: =SUMIF(עסקאות!$D$2:$D$108,$A13,עסקאות!$J$2:$J$108) | G13: =IF(E13=0,"",F13/E13)
... A23: MSTR | B23: =COUNTIF(עסקאות!$D$2:$D$108,$A23) | C23: =COUNTIFS(עסקאות!$D$2:$D$108,$A23,עסקאות!$J$2:$J$108,">0") | D23: =SUMIF(עסקאות!$D$2:$D$108,$A23,עסקאות!$F$2:$F$108) | E23: =SUMIF(עסקאות!$D$2:$D$108,$A23,עסקאות!$K$2:$K$108) | F23: =SUMIF(עסקאות!$D$2:$D$108,$A23,עסקאות!$J$2:$J$108) | G23: =IF(E23=0,"",F23/E23)
A24: סה"כ | B24: =SUM(B2:B23) | C24: =SUM(C2:C23) | D24: =SUM(D2:D23) | E24: =SUM(E2:E23) | F24: =SUM(F2:F23) | G24: =IF(E24=0,"",F24/E24)
A26: אחוז מהפרמיה בחוזים עתידיים אינו בר-פירוש — שם העלות היא נושׁנל ולא פרמיה.

Sheet לפי יום
A1: תאריך | B1: יום | C1: יציאות | D1: זוכות | E1: תוצאה נטו ($) | F1: מצטבר ($)
A2: 46258 | B2: שני | C2: =COUNTIF(עסקאות!$A$2:$A$108,$A2) | D2: =COUNTIFS(עסקאות!$A$2:$A$108,$A2,עסקאות!$J$2:$J$108,">0") | E2: =SUMIF(עסקאות!$A$2:$A$108,$A2,עסקאות!$J$2:$J$108) | F2: =E2
A3: 46259 | B3: שלישי | C3: =COUNTIF(עסקאות!$A$2:$A$108,$A3) | D3: =COUNTIFS(עסקאות!$A$2:$A$108,$A3,עסקאות!$J$2:$J$108,">0") | E3: =SUMIF(עסקאות!$A$2:$A$108,$A3,עסקאות!$J$2:$J$108) | F3: =F2+E3
A4: 46260 | B4: רביעי | C4: =COUNTIF(עסקאות!$A$2:$A$108,$A4) | D4: =COUNTIFS(עסקאות!$A$2:$A$108,$A4,עסקאות!$J$2:$J$108,">0") | E4: =SUMIF(עסקאות!$A$2:$A$108,$A4,עסקאות!$J$2:$J$108) | F4: =F3+E4
A5: 46261 | B5: חמישי | C5: =COUNTIF(עסקאות!$A$2:$A$108,$A5) | D5: =COUNTIFS(עסקאות!$A$2:$A$108,$A5,עסקאות!$J$2:$J$108,">0") | E5: =SUMIF(עסקאות!$A$2:$A$108,$A5,עסקאות!$J$2:$J$108) | F5: =F4+E5
A6: 46262 | B6: שישי | C6: =COUNTIF(עסקאות!$A$2:$A$108,$A6) | D6: =COUNTIFS(עסקאות!$A$2:$A$108,$A6,עסקאות!$J$2:$J$108,">0") | E6: =SUMIF(עסקאות!$A$2:$A$108,$A6,עסקאות!$J$2:$J$108) | F6: =F5+E6
B7: סה"כ | C7: =SUM(C2:C6) | D7: =SUM(D2:D6) | E7: =SUM(E2:E6)

Sheet סינון
A1: שלב | B1: שורות | C1: השפעה על התוצאה ($)
A2: סה"כ עסקאות שנמשכו מ-IBKR | B2: 716 | C2: 5547.22
A3: (-) עסקאות במניות עצמן | B3: -16 | C3: 2408.2
A4: (-) מכירות ב-0 ללא פוזיציה פתוחה — שאריות ריסטרט | B4: -3 | C4: 0
A5: (=) שורות פקיעה — נזקפות כהפסד מלא | B5: 5 | C5: -11171
A6: (-) רגלי BUY | B6: -335 | C6: 5064.34
A7: (-) טיקרים שאינם ברשימה שנמסרה | B7: -46 | C7: 11606.97
A8: (-) פוזיציות שהועברו ללילה (ANET, MRNA) | B8: -9 | C8: 2519.7
A9: =הסט המסונן (גיליון "עסקאות") | B9: =SUM(B2:B8) | C9: =SUM(C2:C8)
A10: בדיקת התאמה מול גיליון העסקאות | C10: ='עסקאות'!J109
